[32m2024-08-02 15:22:43 +0000[0m - dagster - [34mDEBUG[0m - __ASSET_JOB - 184f3396-54ef-495d-aef0-f559b3ced77f - 13717 - LOGS_CAPTURED - Started capturing logs in process (pid: 13717).
[32m2024-08-02 15:22:43 +0000[0m - dagster - [34mDEBUG[0m - __ASSET_JOB - 184f3396-54ef-495d-aef0-f559b3ced77f - 13717 - hackernews_wordcloud - STEP_RESTARTED - Started re-execution (attempt # 6) of step "hackernews_wordcloud".
[32m2024-08-02 15:22:43 +0000[0m - dagster - [34mERROR[0m - [31m__ASSET_JOB - 184f3396-54ef-495d-aef0-f559b3ced77f - 13717 - hackernews_wordcloud - STEP_FAILURE - Execution of step "hackernews_wordcloud" failed.

Exceeded max_retries of 5:

RuntimeError: fake failure

Stack Trace:
  File "/usr/local/python/3.10.13/lib/python3.10/site-packages/dagster/_core/execution/plan/utils.py", line 54, in op_execution_error_boundary
    yield
  File "/usr/local/python/3.10.13/lib/python3.10/site-packages/dagster/_utils/__init__.py", line 473, in iterate_with_context
    next_output = next(iterator)
  File "/usr/local/python/3.10.13/lib/python3.10/site-packages/dagster/_core/execution/plan/compute_generator.py", line 141, in _coerce_op_compute_fn_to_iterator
    result = invoke_compute_fn(
  File "/usr/local/python/3.10.13/lib/python3.10/site-packages/dagster/_core/execution/plan/compute_generator.py", line 129, in invoke_compute_fn
    return fn(context, **args_to_pass) if context_arg_provided else fn(**args_to_pass)
  File "/workspaces/ETL-to-Dagster/hn_dagster.py", line 10, in hackernews_wordcloud
    raise RuntimeError("fake failure")
[0m
